Workbook
Name OBSUMM: REZ!$G$38

Sheet 1
A1: Signal: O1_905564632403,D\FID1A,ch
A4: Peak # | B4: Ret Time | C4: Type | D4: Width | E4: Area | F4: Start Time | G4: End Time
A5: 1 | B5: 0.518 | C5: BV | D5: 0.008 | E5: 139674705 | F5: 0.497 | G5: 0.529
A6: 2 | B6: 0.535 | C6: VV | D6: 0.006 | E6: 178773351 | F6: 0.529 | G6: 0.543
A7: 3 | B7: 0.549 | C7: VV | D7: 0.013 | E7: 18686613498 | F7: 0.543 | G7: 0.6
A8: 4 | B8: 0.607 | C8: VV | D8: 0.023 | E8: 6326497 | F8: 0.6 | G8: 0.654
A9: 5 | B9: 0.662 | C9: VV | D9: 0.022 | E9: 2197053 | F9: 0.654 | G9: 0.69
A10: 6 | B10: 0.702 | C10: VV | D10: 0.013 | E10: 7041375 | F10: 0.69 | G10: 0.796
A11: 7 | B11: 0.88 | C11: VV | D11: 0.011 | E11: 1147190 | F11: 0.867 | G11: 0.975
A12: 8 | B12: 5.575 | C12: BB | D12: 0.016 | E12: 78841 | F12: 5.544 | G12: 5.601
A13: 9 | B13: 6.594 | C13: M | D13: 0.018 | E13: 105127 | F13: 6.577 | G13: 6.63
A14: 10 | B14: 6.708 | C14: BB | D14: 0.016 | E14: 2950004 | F14: 6.635 | G14: 6.75
A15: 11 | B15: 6.96 | C15: BB | D15: 0.016 | E15: 183235 | F15: 6.923 | G15: 6.995
A16: 12 | B16: 7.236 | C16: BB | D16: 0.017 | E16: 48521 | F16: 7.205 | G16: 7.265
... A41: 37 | B41: 12.456 | C41: VB | D41: 0.023 | E41: 279509 | F41: 12.43 | G41: 12.49

Sheet REZ
A1: ='1'!A1 -> Signal: O1_905564632403,D\FID1A,ch | F1: SPECT- A | G1: SPECT- B | H1: RASCH-K | I1: OTN | J1: PASP
A2: SELECT | E2: RT | F2: S | H2: FAME ST 0.5 | I2: 2 | J2: =I2*2 -> 4 | K2: K-1 | L2: K-2 | O2: %
B3: 1 | C3: Декановая | D3: C10:0 | F3: =IF( E3="", "", IF( ISNA(MATCH(E3,SPECOCRUG!$A:$A,0)), 0, OFFSET( SPECOCRUG!$A$1, MATCH(E3,SPECOCRUG!$A:$A,0)-1, 1 ) ) ) | G3: =F3 | H3: 0 | I3: 2 | J3: =I3*2 -> 4 | M3: =IFERROR(F3/L3,0) -> 0 | O3: =IFERROR(G3*100/OBSUMM,0) -> 0
B4: 2 | C4: Ундециловая | D4: С11:0 | F4: =IF( E4="", "", IF( ISNA(MATCH(E4,SPECOCRUG!$A:$A,0)), 0, OFFSET( SPECOCRUG!$A$1, MATCH(E4,SPECOCRUG!$A:$A,0)-1, 1 ) ) ) | G4: =F4 | H4: 15015883 | I4: 1 | J4: =I4*2 -> 2 | K4: =IFERROR(H4/10938814,0) -> 1.3727158 | L4: =K4/I4 -> 1.3727158 | M4: =IFERROR(F4/L4,0) -> 0 | N4: =M4 -> 0 | O4: =IFERROR(G4*100/OBSUMM,0) -> 0
B5: 3 | C5: Лауриновая | D5: С12:0 | F5: =IF( E5="", "", IF( ISNA(MATCH(E5,SPECOCRUG!$A:$A,0)), 0, OFFSET( SPECOCRUG!$A$1, MATCH(E5,SPECOCRUG!$A:$A,0)-1, 1 ) ) ) | G5: =F5 | H5: 20176336 | I5: 2 | J5: =I5*2 -> 4 | K5: =IFERROR(H5/10938814,0) -> 1.844472 | L5: =K5/I5 -> 0.92223599 | M5: =IFERROR(F5/L5,0) -> 0 | N5: =M5 -> 0 | O5: =IFERROR(G5*100/OBSUMM,0) -> 0
B6: 4 | C6: Тридекановая | D6: С13:0 | F6: =IF( E6="", "", IF( ISNA(MATCH(E6,SPECOCRUG!$A:$A,0)), 0, OFFSET( SPECOCRUG!$A$1, MATCH(E6,SPECOCRUG!$A:$A,0)-1, 1 ) ) ) | G6: =F6 | H6: 12196648 | I6: 1 | J6: =I6*2 -> 2 | K6: =IFERROR(H6/10938814,0) -> 1.1149882 | L6: =K6/I6 -> 1.1149882 | M6: =IFERROR(F6/L6,0) -> 0 | N6: =M6 -> 0 | O6: =IFERROR(G6*100/OBSUMM,0) -> 0
B7: 5 | C7: Миристолеиновая* | D7: С14:1 | F7: =IF( E7="", "", IF( ISNA(MATCH(E7,SPECOCRUG!$A:$A,0)), 0, OFFSET( SPECOCRUG!$A$1, MATCH(E7,SPECOCRUG!$A:$A,0)-1, 1 ) ) ) | G7: =F7 | H7: 12140723 | I7: 1 | J7: =I7*2 -> 2 | K7: =IFERROR(H7/10938814,0) -> 1.1098756 | L7: =K7/I7 -> 1.1098756 | M7: =IFERROR(F7/L7,0) -> 0 | N7: =M7 -> 0 | O7: =IFERROR(G7*100/OBSUMM,0) -> 0
B8: 6 | C8: Миристиновая* | D8: С14:0 | F8: =IF( E8="", "", IF( ISNA(MATCH(E8,SPECOCRUG!$A:$A,0)), 0, OFFSET( SPECOCRUG!$A$1, MATCH(E8,SPECOCRUG!$A:$A,0)-1, 1 ) ) ) | G8: =F8 | H8: 24034399 | I8: 2 | J8: =I8*2 -> 4 | K8: =IFERROR(H8/10938814,0) -> 2.1971668 | L8: =K8/I8 -> 1.0985834 | M8: =IFERROR(F8/L8,0) -> 0 | N8: =M8 -> 0 | O8: =IFERROR(G8*100/OBSUMM,0) -> 0
B9: 7 | C9: Цис-10-Петадеценовая | D9: С15:1 | F9: =IF( E9="", "", IF( ISNA(MATCH(E9,SPECOCRUG!$A:$A,0)), 0, OFFSET( SPECOCRUG!$A$1, MATCH(E9,SPECOCRUG!$A:$A,0)-1, 1 ) ) ) | I9: 1 | J9: =I9*2 -> 2 | K9: =IFERROR(H9/10938814,0) -> 0 | L9: =K9/I9 -> 0 | M9: =IFERROR(F9/L9,0) -> 0 | N9: =M9 -> 0 | O9: =IFERROR(G9*100/OBSUMM,0) -> 0
B10: 8 | C10: Пентадекановая* | D10: С15:0 | F10: =IF( E10="", "", IF( ISNA(MATCH(E10,SPECOCRUG!$A:$A,0)), 0, OFFSET( SPECOCRUG!$A$1, MATCH(E10,SPECOCRUG!$A:$A,0)-1, 1 ) ) ) | G10: =F10 | H10: 11750725 | I10: 1 | J10: =I10*2 -> 2 | K10: =IFERROR(H10/10938814,0) -> 1.0742229 | L10: =K10/I10 -> 1.0742229 | M10: =IFERROR(F10/L10,0) -> 0 | N10: =M10 -> 0 | O10: =IFERROR(G10*100/OBSUMM,0) -> 0
B11: 9 | C11: Пальмитолениновая* | D11: С16:1n7 | E11: 6.6 | F11: =IF( E11="", "", IF( ISNA(MATCH(E11,SPECOCRUG!$A:$A,0)), 0, OFFSET( SPECOCRUG!$A$1, MATCH(E11,SPECOCRUG!$A:$A,0)-1, 1 ) ) ) -> 105127 | G11: =F11 -> 105127 | H11: 10985443 | I11: 1 | J11: =I11*2 -> 2 | K11: =IFERROR(H11/10938814,0) -> 1.0042627 | L11: =K11/I11 -> 1.0042627 | M11: =IFERROR(F11/L11,0) -> 104680.78 | N11: =M11 -> 104680.78 | O11: =IFERROR(G11*100/OBSUMM,0) -> 0.76767335
B12: 10 | C12: Пальмитиновая* | D12: С16:0 | E12: 6.7 | F12: =IF( E12="", "", IF( ISNA(MATCH(E12,SPECOCRUG!$A:$A,0)), 0, OFFSET( SPECOCRUG!$A$1, MATCH(E12,SPECOCRUG!$A:$A,0)-1, 1 ) ) ) -> 2950004 | G12: =F12 -> 2950004 | H12: 33841508 | I12: 3 | J12: =I12*2 -> 6 | K12: =IFERROR(H12/10938814,0) -> 3.0937091 | L12: =K12/I12 -> 1.0312364 | M12: =IFERROR(F12/L12,0) -> 2860647.8 | N12: =M12 -> 2860647.8 | O12: =IFERROR(G12*100/OBSUMM,0) -> 21.541939
B13: 11 | C13: Цис-10-Гептадеценовая* | D13: С17:1n7 | F13: =IF( E13="", "", IF( ISNA(MATCH(E13,SPECOCRUG!$A:$A,0)), 0, OFFSET( SPECOCRUG!$A$1, MATCH(E13,SPECOCRUG!$A:$A,0)-1, 1 ) ) ) | G13: =F13 | H13: 10938814 | I13: 1 | J13: =I13*2 -> 2 | K13: =IFERROR(H13/10938814,0) -> 1 | L13: =K13/I13 -> 1 | M13: =IFERROR(F13/L13,0) -> 0 | N13: =M13 -> 0 | O13: =IFERROR(G13*100/OBSUMM,0) -> 0
B14: 12 | C14: Маргариновая | D14: С17:0 | F14: =IF( E14="", "", IF( ISNA(MATCH(E14,SPECOCRUG!$A:$A,0)), 0, OFFSET( SPECOCRUG!$A$1, MATCH(E14,SPECOCRUG!$A:$A,0)-1, 1 ) ) ) | G14: =F14 | H14: 5174874 | I14: 1 | J14: =I14*2 -> 2 | K14: =IFERROR(H14/10938814,0) -> 0.4730745 | L14: =K14/I14 -> 0.4730745 | M14: =IFERROR(F14/L14,0) -> 0 | N14: =M14 -> 0 | O14: =IFERROR(G14*100/OBSUMM,0) -> 0
B15: 13 | C15: γ-Линоленовая* | D15: C18:3n6 | E15: 7.5 | F15: =IF( E15="", "", IF( ISNA(MATCH(E15,SPECOCRUG!$A:$A,0)), 0, OFFSET( SPECOCRUG!$A$1, MATCH(E15,SPECOCRUG!$A:$A,0)-1, 1 ) ) ) -> 27007 | G15: =F15 -> 27007 | H15: 3192318 | I15: 1 | J15: 2 | K15: =IFERROR(H15/10938814,0) -> 0.29183401 | L15: =K15/I15 -> 0.29183401 | M15: =IFERROR(F15/L15,0) -> 92542.331 | N15: =M15 -> 92542.331 | O15: =IFERROR(G15*100/OBSUMM,0) -> 0.19721436
B16: 14 | C16: Линолевая* | D16: С18:2n6c | E16: 7.6 | F16: =IF( E16="", "", IF( ISNA(MATCH(E16,SPECOCRUG!$A:$A,0)), 0, OFFSET( SPECOCRUG!$A$1, MATCH(E16,SPECOCRUG!$A:$A,0)-1, 1 ) ) ) -> 4083828 | G16: =F16 -> 4083828 | H16: 10298554 | I16: 1 | J16: =I16*2 -> 2 | K16: =IFERROR(H16/10938814,0) -> 0.94146897 | L16: =K16/I16 -> 0.94146897 | M16: =IFERROR(F16/L16,0) -> 4337719.1 | N16: =M16 -> 4337719.1 | O16: =IFERROR(G16*100/OBSUMM,0) -> 29.82151
B17: 15 | C17: Олеиновая******* | D17: C18:1n9c | E17: 7.7 | F17: =IF( E16="", "", IF( ISNA(MATCH(E16,SPECOCRUG!$A:$A,0)), 0, OFFSET( SPECOCRUG!$A$1, MATCH(E16,SPECOCRUG!$A:$A,0)-0, 1 ) ) ) -> 1843336 | G17: =F17 -> 1843336 | H17: 52829014 | I17: 5 | J17: 6 | K17: =IFERROR(H17/10938814,0) -> 4.8295011 | L17: =K17/I17 -> 0.96590022 | M17: =IFERROR(F17/L17,0) -> 1908412.5 | N17: =M17 -> 1908412.5 | O17: =IFERROR(G17*100/OBSUMM,0) -> 13.460671
B18: 16 | C18: Линоленовая* | D18: C18:3n3 | F18: =IF( E16="", "", IF( ISNA(MATCH(E16,SPECOCRUG!$A:$A,0)), 0, OFFSET( SPECOCRUG!$A$1, MATCH(E16,SPECOCRUG!$A:$A,0)+1, 1 ) ) ) -> 180119 | G18: =F18 -> 180119 | I18: 1 | J18: =I18*2 -> 2 | K18: =IFERROR(H18/10938814,0) -> 0 | L18: =K18/I18 -> 0 | M18: =IFERROR(F18/L18,0) -> 0 | N18: =M18 -> 0 | O18: =IFERROR(G18*100/OBSUMM,0) -> 1.3152906
B19: 17 | C19: ПУНИЧЕСКАЯ | F19: =IF( E19="", "", IF( ISNA(MATCH(E19,SPECOCRUG!$A:$A,0)), 0, OFFSET( SPECOCRUG!$A$1, MATCH(E19,SPECOCRUG!$A:$A,0)-1, 1 ) ) ) | G19: =F19 | I19: 1 | J19: =I19*2 -> 2 | K19: =IFERROR(H19/10938814,0) -> 0 | L19: =K19/I19 -> 0 | M19: =IFERROR(F19/L19,0) -> 0 | N19: =M19 -> 0 | O19: =IFERROR(G19*100/OBSUMM,0) -> 0
B20: 18 | C20: Элаидиновая******* | D20: C18:1n9t | F20: =IF( E20="", "", IF( ISNA(MATCH(E20,SPECOCRUG!$A:$A,0)), 0, OFFSET( SPECOCRUG!$A$1, MATCH(E20,SPECOCRUG!$A:$A,0)-1, 1 ) ) ) | G20: =F20 | I20: 1 | J20: =I20*2 -> 2 | K20: =IFERROR(H20/10938814,0) -> 0 | L20: =K20/I20 -> 0 | M20: =IFERROR(F20/L20,0) -> 0 | N20: =M20 -> 0 | O20: =IFERROR(G20*100/OBSUMM,0) -> 0
B21: 19 | C21: Стеариновая* | D21: C18:0 | E21: 7.7 | F21: =IF( E21="", "", IF( ISNA(MATCH(E21,SPECOCRUG!$A:$A,0)), 0, OFFSET( SPECOCRUG!$A$1, MATCH(E21,SPECOCRUG!$A:$A,0)-1, 1 ) ) ) -> 1530090 | G21: =F21 -> 1530090 | H21: 21301650 | I21: 2 | J21: =I21*2 -> 4 | K21: =IFERROR(H21/10938814,0) -> 1.9473455 | L21: =K21/I21 -> 0.97367274 | M21: =IFERROR(F21/L21,0) -> 1571462.3 | N21: =M21 -> 1571462.3 | O21: =IFERROR(G21*100/OBSUMM,0) -> 11.173241
B22: 20 | C22: Арахидоновая* | D22: C20:4n6 | E22: 8.4 | F22: =IF( E22="", "", IF( ISNA(MATCH(E22,SPECOCRUG!$A:$A,0)), 0, OFFSET( SPECOCRUG!$A$1, MATCH(E22,SPECOCRUG!$A:$A,0)-1, 1 ) ) ) -> 1506582 | G22: =F22 -> 1506582 | H22: 8835632 | I22: 1 | J22: =I22*2 -> 2 | K22: =IFERROR(H22/10938814,0) -> 0.80773217 | L22: =K22/I22 -> 0.80773217 | M22: =IFERROR(F22/L22,0) -> 1865199.9 | N22: =M22 -> 1865199.9 | O22: =IFERROR(G22*100/OBSUMM,0) -> 11.001578
B23: 21 | C23: Эйкозопентаеновая* | D23: C20:5 | E23: =E22 -> 8.4 | F23: =IF( E22="", "", IF( ISNA(MATCH(E22,SPECOCRUG!$A:$A,0)), 0, OFFSET( SPECOCRUG!$A$1, MATCH(E22,SPECOCRUG!$A:$A,0)-0, 1 ) ) ) -> 47285 | G23: =F23 -> 47285 | H23: 10083898 | I23: 1 | J23: =I23*2 -> 2 | K23: =IFERROR(H23/10938814,0) -> 0.92184564 | L23: =K23/I23 -> 0.92184564 | M23: =IFERROR(F23/L23,0) -> 51293.837 | N23: =M23 -> 51293.837 | O23: =IFERROR(G23*100/OBSUMM,0) -> 0.34529126
B24: 22 | C24: цис-8,11,14-эйкозатриеновая 320* | D24: C20:3n8 | E24: =E21 -> 7.7 | F24: =IF( E22="", "", IF( ISNA(MATCH(E22,SPECOCRUG!$A:$A,0)), 0, OFFSET( SPECOCRUG!$A$1, MATCH(E22,SPECOCRUG!$A:$A,0)+1, 1 ) ) ) -> 152229 | G24: =F24 -> 152229 | H24: 7506559 | I24: 1 | J24: =I24*2 -> 2 | K24: =IFERROR(H24/10938814,0) -> 0.68623152 | L24: =K24/I24 -> 0.68623152 | M24: =IFERROR(F24/L24,0) -> 221833.29 | N24: =M24 -> 221833.29 | O24: =IFERROR(G24*100/OBSUMM,0) -> 1.1116283
B25: 23 | C25: Эйкозадиеновая* | D25: C20:2 | F25: =IF( E25="", "", IF( ISNA(MATCH(E25,SPECOCRUG!$A:$A,0)), 0, OFFSET( SPECOCRUG!$A$1, MATCH(E25,SPECOCRUG!$A:$A,0)-1, 1 ) ) ) | G25: =F25 | H25: 20127460 | I25: 2 | J25: =I25*2 -> 4 | K25: =IFERROR(H25/10938814,0) -> 1.8400039 | L25: =K25/I25 -> 0.92000193 | M25: =IFERROR(F25/L25,0) -> 0 | N25: =M25 -> 0 | O25: =IFERROR(G25*100/OBSUMM,0) -> 0
B26: 24 | C26: Эйкозеновая* | D26: C20:1 | F26: =IF( E26="", "", IF( ISNA(MATCH(E26,SPECOCRUG!$A:$A,0)), 0, OFFSET( SPECOCRUG!$A$1, MATCH(E26,SPECOCRUG!$A:$A,0)-1, 1 ) ) ) | G26: =F26 | I26: 1 | J26: =I26*2 -> 2 | K26: =IFERROR(H26/10938814,0) -> 0 | L26: =K26/I26 -> 0 | M26: =IFERROR(F26/L26,0) -> 0 | N26: =M26 -> 0 | O26: =IFERROR(G26*100/OBSUMM,0) -> 0
B27: 25 | C27: цис-11,14,17-эйкозатриеновая* | D27: C20:3n11 | F27: =IF( E27="", "", IF( ISNA(MATCH(E27,SPECOCRUG!$A:$A,0)), 0, OFFSET( SPECOCRUG!$A$1, MATCH(E27,SPECOCRUG!$A:$A,0)-1, 1 ) ) ) | G27: =F27 | I27: 1 | J27: =I27*2 -> 2 | K27: =IFERROR(H27/10938814,0) -> 0 | L27: =K27/I27 -> 0 | M27: =IFERROR(F27/L27,0) -> 0 | N27: =M27 -> 0 | O27: =IFERROR(G27*100/OBSUMM,0) -> 0
B28: 26 | C28: Арахиновая* | D28: C20:0 | F28: =IF( E28="", "", IF( ISNA(MATCH(E28,SPECOCRUG!$A:$A,0)), 0, OFFSET( SPECOCRUG!$A$1, MATCH(E28,SPECOCRUG!$A:$A,0)-1, 1 ) ) ) | G28: =F28 | H28: 19575761 | I28: 2 | J28: =I28*2 -> 4 | K28: =IFERROR(H28/10938814,0) -> 1.7895689 | L28: =K28/I28 -> 0.89478443 | M28: =IFERROR(F28/L28,0) -> 0 | N28: =M28 -> 0 | O28: =IFERROR(G28*100/OBSUMM,0) -> 0
B29: 27 | C29: Генэйкозановая | D29: С21:0 | F29: =IF( E29="", "", IF( ISNA(MATCH(E29,SPECOCRUG!$A:$A,0)), 0, OFFSET( SPECOCRUG!$A$1, MATCH(E29,SPECOCRUG!$A:$A,0)-1, 1 ) ) ) | G29: =F29 | H29: 9819618 | I29: 1 | J29: =I29*2 -> 2 | K29: =IFERROR(H29/10938814,0) -> 0.8976858 | L29: =K29/I29 -> 0.8976858 | M29: =IFERROR(F29/L29,0) -> 0 | N29: =M29 -> 0 | O29: =IFERROR(G29*100/OBSUMM,0) -> 0
B30: 28 | C30: Докозадиеновая | D30: C22:2 | F30: =IF( E30="", "", IF( ISNA(MATCH(E30,SPECOCRUG!$A:$A,0)), 0, OFFSET( SPECOCRUG!$A$1, MATCH(E30,SPECOCRUG!$A:$A,0)-1, 1 ) ) ) | G30: =F30 | H30: 7439773 | I30: 1 | J30: =I30*2 -> 2 | K30: =IFERROR(H30/10938814,0) -> 0.68012611 | L30: =K30/I30 -> 0.68012611 | M30: =IFERROR(F30/L30,0) -> 0 | N30: =M30 -> 0 | O30: =IFERROR(G30*100/OBSUMM,0) -> 0
B31: 29 | C31: Эруковая* | D31: C22:1 | F31: =IF( E31="", "", IF( ISNA(MATCH(E31,SPECOCRUG!$A:$A,0)), 0, OFFSET( SPECOCRUG!$A$1, MATCH(E31,SPECOCRUG!$A:$A,0)-1, 1 ) ) ) | G31: =F31 | H31: 11600382 | I31: 1 | J31: =I31*2 -> 2 | K31: =IFERROR(H31/10938814,0) -> 1.060479 | L31: =K31/I31 -> 1.060479 | M31: =IFERROR(F31/L31,0) -> 0 | N31: =M31 -> 0 | O31: =IFERROR(G31*100/OBSUMM,0) -> 0
B32: 30 | C32: Докозагексаеновая* no | D32: C22:6 | E32: 9.2 | F32: =IF( E32="", "", IF( ISNA(MATCH(E32,SPECOCRUG!$A:$A,0)), 0, OFFSET( SPECOCRUG!$A$1, MATCH(E32,SPECOCRUG!$A:$A,0)-1, 1 ) ) ) -> 358357 | G32: =F32 -> 358357 | H32: 9511152 | I32: 1 | J32: =I32*2 -> 2 | K32: =IFERROR(H32/10938814,0) -> 0.86948658 | L32: =K32/I32 -> 0.86948658 | M32: =IFERROR(F32/L32,0) -> 412147.82 | N32: =M32 -> 412147.82 | O32: =IFERROR(G32*100/OBSUMM,0) -> 2.6168455
B33: 31 | C33: Docosapenaenoic acid no | D33: c22:4 | E33: =E32 -> 9.2 | F33: =IF( E32="", "", IF( ISNA(MATCH(E32,SPECOCRUG!$A:$A,0)), 0, OFFSET( SPECOCRUG!$A$1, MATCH(E32,SPECOCRUG!$A:$A,0)-0, 1 ) ) ) -> 188950 | G33: =F33 -> 188950 | H33: 9512456 | I33: 1 | J33: =I33*2 -> 2 | K33: =IFERROR(H33/10938814,0) -> 0.86960579 | L33: =K33/I33 -> 0.86960579 | M33: =IFERROR(F33/L33,0) -> 217282.36 | N33: =M33 -> 217282.36 | O33: =IFERROR(G33*100/OBSUMM,0) -> 1.3797776
B34: 32 | C34: Докозатетраеновая | D34: C22:5 | E34: =E32 -> 9.2 | F34: =IF( E32="", "", IF( ISNA(MATCH(E32,SPECOCRUG!$A:$A,0)), 0, OFFSET( SPECOCRUG!$A$1, MATCH(E32,SPECOCRUG!$A:$A,0)+1, 1 ) ) ) -> 134592 | G34: =F34 -> 134592 | H34: 18782933 | I34: 2 | J34: =I34*2 -> 4 | K34: =IFERROR(H34/10938814,0) -> 1.7170904 | L34: =K34/I34 -> 0.85854522 | M34: =IFERROR(F34/L34,0) -> 156767.51 | N34: =M34 -> 156767.51 | O34: =IFERROR(G34*100/OBSUMM,0) -> 0.98283687
B35: 33 | C35: Трикозановая | D35: C23:0 | F35: =IF( E35="", "", IF( ISNA(MATCH(E35,SPECOCRUG!$A:$A,0)), 0, OFFSET( SPECOCRUG!$A$1, MATCH(E35,SPECOCRUG!$A:$A,0)-1, 1 ) ) ) | G35: =F35 | H35: 9047658 | I35: 1 | J35: =I35*2 -> 2 | K35: =IFERROR(H35/10938814,0) -> 0.82711508 | L35: =K35/I35 -> 0.82711508 | M35: =IFERROR(F35/L35,0) -> 0 | N35: =M35 -> 0 | O35: =IFERROR(G35*100/OBSUMM,0) -> 0
B36: 34 | C36: Нервоновая* | D36: C24:1n9 | E36: 10.3 | F36: =IF( E36="", "", IF( ISNA(MATCH(E36,SPECOCRUG!$A:$A,0)), 0, OFFSET( SPECOCRUG!$A$1, MATCH(E36,SPECOCRUG!$A:$A,0)-1, 1 ) ) ) -> 328122 | G36: =F36 -> 328122 | H36: 9593474 | I36: 1 | J36: =I36*2 -> 2 | K36: =IFERROR(H36/10938814,0) -> 0.87701226 | L36: =K36/I36 -> 0.87701226 | M36: =IFERROR(F36/L36,0) -> 374136.16 | N36: =M36 -> 374136.16 | O36: =IFERROR(G36*100/OBSUMM,0) -> 2.3960592
B37: 35 | C37: Лигноцериновая | D37: C24:0 | E37: 10.4 | F37: =IF( E37="", "", IF( ISNA(MATCH(E37,SPECOCRUG!$A:$A,0)), 0, OFFSET( SPECOCRUG!$A$1, MATCH(E37,SPECOCRUG!$A:$A,0)-1, 1 ) ) ) -> 258608 | G37: =F37 -> 258608 | H37: 18413624 | I37: 2 | J37: =I37*2 -> 4 | K37: =IFERROR(H37/10938814,0) -> 1.6833291 | L37: =K37/I37 -> 0.84166455 | M37: =IFERROR(F37/L37,0) -> 307257.8 | N37: =M37 -> 307257.8 | O37: =IFERROR(G37*100/OBSUMM,0) -> 1.8884442
G38: =SUM(G3:G37) -> 13694236 | N38: =SUM(N4:N37) -> 14481384 | O38: =SUM(O3:O37) -> 100 | P38: O-INDEX
D39: MIN | E39: MAX | G39: =G32+G23+G34 -> 540234 | N39: =N23+N32 -> 463441.66 | P39: =N39*100/OBSUMM -> 3.3842097
A40: ДГК | B40: C22:6 | C40: =O32 -> 2.6168455 | D40: 2.02 | E40: 6.287 | G40: O-INDEX
...

Sheet SPECOCRUG
A2: =ROUND('1'!B5, 1) -> 0.5 | B2: ='1'!E5 -> 139674705
A3: =ROUND('1'!B6, 1) -> 0.5 | B3: ='1'!E6 -> 178773351
A4: =ROUND('1'!B7, 1) -> 0.5 | B4: ='1'!E7 -> 18686613498
A5: =ROUND('1'!B8, 1) -> 0.6 | B5: ='1'!E8 -> 6326497
A6: =ROUND('1'!B9, 1) -> 0.7 | B6: ='1'!E9 -> 2197053
A7: =ROUND('1'!B10, 1) -> 0.7 | B7: ='1'!E10 -> 7041375
A8: =ROUND('1'!B11, 1) -> 0.9 | B8: ='1'!E11 -> 1147190
A9: =ROUND('1'!B12, 1) -> 5.6 | B9: ='1'!E12 -> 78841
A10: =ROUND('1'!B13, 1) -> 6.6 | B10: ='1'!E13 -> 105127
A11: =ROUND('1'!B14, 1) -> 6.7 | B11: ='1'!E14 -> 2950004
A12: =ROUND('1'!B15, 1) -> 7 | B12: ='1'!E15 -> 183235
A13: =ROUND('1'!B16, 1) -> 7.2 | B13: ='1'!E16 -> 48521
... A326: =ROUND('1'!B329, 1) -> 0 | B326: ='1'!E329 -> 0
